<?xml version="1.0" encoding="UTF-8"?>
<testng-results skipped="0" failed="2" ignored="0" total="4" passed="2">
  <reporter-output>
  </reporter-output>
  <suite name="Listeners TestSuite" duration-ms="162" started-at="2021-04-02T18:28:55Z" finished-at="2021-04-02T18:28:55Z">
    <groups>
    </groups>
    <test name="Application Test 1" duration-ms="58" started-at="2021-04-02T18:28:55Z" finished-at="2021-04-02T18:28:55Z">
      <class name="testngasserts.Testng_Listeners2">
        <test-method status="PASS" signature="setUp()[pri:0, instance:testngasserts.Testng_Listeners2@100fc185]" name="setUp" is-config="true" duration-ms="16" started-at="2021-04-02T18:28:55Z" finished-at="2021-04-02T18:28:55Z">
          <reporter-output>
          </reporter-output>
        </test-method> <!-- setUp -->
        <test-method status="PASS" signature="testMethod1()[pri:0, instance:testngasserts.Testng_Listeners2@100fc185]" name="testMethod1" duration-ms="8" started-at="2021-04-02T18:28:55Z" finished-at="2021-04-02T18:28:55Z">
          <reporter-output>
          </reporter-output>
        </test-method> <!-- testMethod1 -->
        <test-method status="FAIL" signature="testMethod2()[pri:0, instance:testngasserts.Testng_Listeners2@100fc185]" name="testMethod2" duration-ms="4" started-at="2021-04-02T18:28:55Z" finished-at="2021-04-02T18:28:55Z">
          <exception class="java.lang.AssertionError">
            <message>
              <![CDATA[expected [true] but found [false]]]>
            </message>
            <full-stacktrace>
              <![CDATA[java.lang.AssertionError: expected [true] but found [false]
at org.testng.Assert.fail(Assert.java:96)
at org.testng.Assert.failNotEquals(Assert.java:776)
at org.testng.Assert.assertTrue(Assert.java:44)
at org.testng.Assert.assertTrue(Assert.java:54)
at testngasserts.Testng_Listeners2.testMethod2(Testng_Listeners2.java:37)
at sun.reflect.NativeMethodAccessorImpl.invoke0(Native Method)
at sun.reflect.NativeMethodAccessorImpl.invoke(Unknown Source)
at sun.reflect.DelegatingMethodAccessorImpl.invoke(Unknown Source)
at java.lang.reflect.Method.invoke(Unknown Source)
at org.testng.internal.MethodInvocationHelper.invokeMethod(MethodInvocationHelper.java:124)
at org.testng.internal.Invoker.invokeMethod(Invoker.java:580)
at org.testng.internal.Invoker.invokeTestMethod(Invoker.java:716)
at org.testng.internal.Invoker.invokeTestMethods(Invoker.java:988)
at org.testng.internal.TestMethodWorker.invokeTestMethods(TestMethodWorker.java:125)
at org.testng.internal.TestMethodWorker.run(TestMethodWorker.java:109)
at org.testng.TestRunner.privateRun(TestRunner.java:648)
at org.testng.TestRunner.run(TestRunner.java:505)
at org.testng.SuiteRunner.runTest(SuiteRunner.java:455)
at org.testng.SuiteRunner.runSequentially(SuiteRunner.java:450)
at org.testng.SuiteRunner.privateRun(SuiteRunner.java:415)
at org.testng.SuiteRunner.run(SuiteRunner.java:364)
at org.testng.SuiteRunnerWorker.runSuite(SuiteRunnerWorker.java:52)
at org.testng.SuiteRunnerWorker.run(SuiteRunnerWorker.java:84)
at org.testng.TestNG.runSuitesSequentially(TestNG.java:1208)
at org.testng.TestNG.runSuitesLocally(TestNG.java:1137)
at org.testng.TestNG.runSuites(TestNG.java:1049)
at org.testng.TestNG.run(TestNG.java:1017)
at org.testng.remote.AbstractRemoteTestNG.run(AbstractRemoteTestNG.java:132)
at org.testng.remote.RemoteTestNG.initAndRun(RemoteTestNG.java:230)
at org.testng.remote.RemoteTestNG.main(RemoteTestNG.java:76)
]]>
            </full-stacktrace>
          </exception> <!-- java.lang.AssertionError -->
          <reporter-output>
          </reporter-output>
        </test-method> <!-- testMethod2 -->
        <test-method status="PASS" signature="cleanUp()[pri:0, instance:testngasserts.Testng_Listeners2@100fc185]" name="cleanUp" is-config="true" duration-ms="1" started-at="2021-04-02T18:28:55Z" finished-at="2021-04-02T18:28:55Z">
          <reporter-output>
          </reporter-output>
        </test-method> <!-- cleanUp -->
      </class> <!-- testngasserts.Testng_Listeners2 -->
    </test> <!-- Application Test 1 -->
    <test name="Application Test 2" duration-ms="10" started-at="2021-04-02T18:28:55Z" finished-at="2021-04-02T18:28:55Z">
      <class name="testngasserts.Testng_Listeners2">
        <test-method status="PASS" signature="setUp()[pri:0, instance:testngasserts.Testng_Listeners2@4b9e13df]" name="setUp" is-config="true" duration-ms="0" started-at="2021-04-02T18:28:55Z" finished-at="2021-04-02T18:28:55Z">
          <reporter-output>
          </reporter-output>
        </test-method> <!-- setUp -->
        <test-method status="PASS" signature="testMethod1()[pri:0, instance:testngasserts.Testng_Listeners2@4b9e13df]" name="testMethod1" duration-ms="1" started-at="2021-04-02T18:28:55Z" finished-at="2021-04-02T18:28:55Z">
          <reporter-output>
          </reporter-output>
        </test-method> <!-- testMethod1 -->
        <test-method status="FAIL" signature="testMethod2()[pri:0, instance:testngasserts.Testng_Listeners2@4b9e13df]" name="testMethod2" duration-ms="2" started-at="2021-04-02T18:28:55Z" finished-at="2021-04-02T18:28:55Z">
          <exception class="java.lang.AssertionError">
            <message>
              <![CDATA[expected [true] but found [false]]]>
            </message>
            <full-stacktrace>
              <![CDATA[java.lang.AssertionError: expected [true] but found [false]
at org.testng.Assert.fail(Assert.java:96)
at org.testng.Assert.failNotEquals(Assert.java:776)
at org.testng.Assert.assertTrue(Assert.java:44)
at org.testng.Assert.assertTrue(Assert.java:54)
at testngasserts.Testng_Listeners2.testMethod2(Testng_Listeners2.java:37)
at sun.reflect.NativeMethodAccessorImpl.invoke0(Native Method)
at sun.reflect.NativeMethodAccessorImpl.invoke(Unknown Source)
at sun.reflect.DelegatingMethodAccessorImpl.invoke(Unknown Source)
at java.lang.reflect.Method.invoke(Unknown Source)
at org.testng.internal.MethodInvocationHelper.invokeMethod(MethodInvocationHelper.java:124)
at org.testng.internal.Invoker.invokeMethod(Invoker.java:580)
at org.testng.internal.Invoker.invokeTestMethod(Invoker.java:716)
at org.testng.internal.Invoker.invokeTestMethods(Invoker.java:988)
at org.testng.internal.TestMethodWorker.invokeTestMethods(TestMethodWorker.java:125)
at org.testng.internal.TestMethodWorker.run(TestMethodWorker.java:109)
at org.testng.TestRunner.privateRun(TestRunner.java:648)
at org.testng.TestRunner.run(TestRunner.java:505)
at org.testng.SuiteRunner.runTest(SuiteRunner.java:455)
at org.testng.SuiteRunner.runSequentially(SuiteRunner.java:450)
at org.testng.SuiteRunner.privateRun(SuiteRunner.java:415)
at org.testng.SuiteRunner.run(SuiteRunner.java:364)
at org.testng.SuiteRunnerWorker.runSuite(SuiteRunnerWorker.java:52)
at org.testng.SuiteRunnerWorker.run(SuiteRunnerWorker.java:84)
at org.testng.TestNG.runSuitesSequentially(TestNG.java:1208)
at org.testng.TestNG.runSuitesLocally(TestNG.java:1137)
at org.testng.TestNG.runSuites(TestNG.java:1049)
at org.testng.TestNG.run(TestNG.java:1017)
at org.testng.remote.AbstractRemoteTestNG.run(AbstractRemoteTestNG.java:132)
at org.testng.remote.RemoteTestNG.initAndRun(RemoteTestNG.java:230)
at org.testng.remote.RemoteTestNG.main(RemoteTestNG.java:76)
]]>
            </full-stacktrace>
          </exception> <!-- java.lang.AssertionError -->
          <reporter-output>
          </reporter-output>
        </test-method> <!-- testMethod2 -->
        <test-method status="PASS" signature="cleanUp()[pri:0, instance:testngasserts.Testng_Listeners2@4b9e13df]" name="cleanUp" is-config="true" duration-ms="1" started-at="2021-04-02T18:28:55Z" finished-at="2021-04-02T18:28:55Z">
          <reporter-output>
          </reporter-output>
        </test-method> <!-- cleanUp -->
      </class> <!-- testngasserts.Testng_Listeners2 -->
    </test> <!-- Application Test 2 -->
  </suite> <!-- Listeners TestSuite -->
</testng-results>
